I'm sorry, but an uncaught exception occurred.

While running game code:
  File "game/scripts/fourth_day_part2.rpy", line 664, in script
    arr "Я работал в игровой корпорации больше десяти лет."
Exception: Sayer 'arr' is not defined.

-- Full Traceback ------------------------------------------------------------

Full traceback:
  File "game/scripts/fourth_day_part2.rpy", line 664, in script
    arr "Я работал в игровой корпорации больше десяти лет."
  File "C:\renpy-8.0.3-sdk\renpy\ast.py", line 881, in execute
    who = eval_who(self.who, self.who_fast)
  File "C:\renpy-8.0.3-sdk\renpy\ast.py", line 774, in eval_who
    raise Exception("Sayer '%s' is not defined." % who)
Exception: Sayer 'arr' is not defined.

Windows-10-10.0.22000 AMD64
Ren'Py 8.0.3.22090809
DGame 1.0
Sun Dec 18 02:52:07 2022
